Workbook

Sheet Cover
A2: UNIT TEST CASE
A4: Project Name | B4: GameRent - Hệ thống cho thuê tài khoản game trực tuyến tự động 24/7 | D4: Creator | E4: Nhóm 15 - Lớp Kiểm thử phần mềm-1-1-26(N05)
A5: Project Code | B5: GAMERENT | D5: Reviewer/Approver | E5: ThS. Phạm Thị Loan
A6: Document Code | B6: =B5&"_"&"TestCase_v1.0" -> GAMERENT_TestCase_v1.0 | D6: Issue Date | E6: 2026-03-24
D7: Version | E7: v1.0
A9: Record of change
A10: Effective Date | B10: Version | C10: Change Item | D10: *A,D,M | E10: Change description | F10: Reference
A11: 2026-03-24 | B11: v1.0 | C11: Initial Release | D11: A | E11: Khởi tạo và hoàn thiện đầy đủ bộ 100 Unit Test Cases cho 10 Module chức năng cốt lõi của dự án GameRent do Nhóm 15 thực hiện (áp dụng kỹ thuật BVA, EP, Decision Table, đặc tả UC1). | F11: CHI_TIET_DU_AN_GAMERENT.md, UC1_Add New Product.pdf

Sheet FunctionList
A2: UNIT TEST CASE LIST
A4: Project Name | B4: =Cover!B4 -> GameRent - Hệ thống cho thuê tài khoản game trực tuyến tự động 24/7
A5: Project Code | B5: =Cover!B5 -> GAMERENT
A6: Normal number of Test cases/KLOC | B6: 100
A7: Test Environment Setup Description | B7: Môi trường kiểm thử đơn vị (Unit Test Environment): 1. Nền tảng: Node.js v20.x, React 19.x, Vite 8.x 2. Framework: Vitest v5.0.1, jsdom simulated DOM environment 3. Cơ sở dữ liệu: LocalStorage Mock Database Engine 4. Tầng logic nghiệp vụ: src/utils/validation.js, favoriteUtils.js 5. Tiêu chuẩn áp dụng: BVA, EP, Decision Table, UC1_Add New Product
A10: No | B10: Requirement Name | C10: Class Name | D10: Function Name | E10: Function Code(Optional) | F10: Sheet Name | G10: Description | H10: Pre-Condition
A11: 1 | B11: Module 1: Xác thực & Đăng ký | C11: validation.js | D11: validateRegistration | E11: F_AUTH_REG | F11: F_AUTH_REG | G11: Kiểm tra hợp lệ form đăng ký tài khoản (BVA 4-30 ký tự, SĐT 10 chữ số, mật khẩu >= 6 ký tự, kiểm tra trùng lặp) | H11: Hệ thống hoạt động bình thường, CSDL có sẵn danh sách user mẫu
A12: 2 | B12: Module 2: Xác thực & Đăng nhập | C12: validation.js | D12: validateLogin | E12: F_AUTH_LOGIN | F12: F_AUTH_LOGIN | G12: Xác thực thông tin đăng nhập email/mật khẩu, chặn tài khoản bị khóa isBlocked, quản lý phiên | H12: Hệ thống có sẵn user thường và user bị khóa (isBlocked=true)
A13: 3 | B13: Module 3: Ví điện tử & Nạp tiền | C13: validation.js | D13: validateDepositAmount | E13: F_WAL_DEP | F13: F_WAL_DEP | G13: Kiểm tra hợp lệ hạn mức nạp tiền ví qua VietQR Auto (BVA 10.000đ - 5.000.000đ, số nguyên dương) | H13: Người dùng đã đăng nhập, mở modal nạp tiền VietQR
A14: 4 | B14: Module 4: Thuê tài khoản game | C14: validation.js | D14: calculateRentalCost | E14: F_RENT_CALC | F14: F_RENT_CALC | G14: Tính chi phí thuê và kiểm tra số dư ví theo Decision Table (BVA 1h - 48h, trạng thái acc, đủ/thiếu ví) | H14: Có tài khoản game trong CSDL, xác định giá thuê/giờ và số dư ví
A15: 5 | B15: Module 5: Quản trị kho tài khoản | C15: validation.js | D15: validateProductUC1 | E15: F_ADM_PROD | F15: F_ADM_PROD | G15: Kiểm tra form Thêm tài khoản game chuẩn 100% tài liệu đặc tả đề bài UC1_Add New Product (BR1-BR6) | H15: Quản trị viên mở modal Thêm mới tài khoản trong kho
A16: 6 | B16: Module 6: Hoàn tiền & Gia hạn | C16: validation.js | D16: calculateRefundAndExtension | E16: F_REF_EXT | F16: F_REF_EXT | G16: Tính hoàn tiền 50% khi trả sớm, hoàn tiền 100% khi khiếu nại được duyệt, và gia hạn thêm giờ thuê | H16: Đơn thuê đang tồn tại trong hệ thống kèm thông tin ca chơi
A17: 7 | B17: Module 7: Tự động đổi mật khẩu | C17: validation.js | D17: generateRandomPassword | E17: F_AUTO_PASS | F17: F_AUTO_PASS | G17: Tự động sinh mật khẩu ngẫu nhiên bảo mật cao (12-14 ký tự) khi thu hồi nick hết giờ, chống trùng pass cũ | H17: Ca thuê hết hạn hoặc Admin thu hồi bảo mật
A18: 8 | B18: Module 8: Đổi mật khẩu cá nhân | C18: validation.js | D18: validatePasswordChange | E18: F_AUTH_CHG_PWD | F18: F_AUTH_CHG_PWD | G18: Kiểm tra hợp lệ form đổi mật khẩu khách thuê (BVA 5-6 ký tự, mật khẩu cũ, khớp mật khẩu xác nhận) | H18: Khách hàng đã đăng nhập tài khoản cá nhân
A19: 9 | B19: Module 9: Quản lý khách hàng CRM | C19: validation.js / context | D19: crudAndAutoSyncCRM | E19: F_CRM_SYNC | F19: F_CRM_SYNC | G19: Thao tác CRUD hồ sơ khách hàng và tự động đồng bộ khách mới khi đăng ký | H19: Đăng ký tài khoản ngoài trang chủ hoặc thao tác trong trang Quản lý khách hàng
A20: 10 | B20: Module 10: Phân tách Yêu thích | C20: favoriteUtils.js | D20: getFavoritesKey | E20: F_FAV_SEP | F20: F_FAV_SEP | G20: Xác định chính xác storage key phân tách danh sách yêu thích độc lập theo User ID | H20: Người dùng thao tác thả tim tài khoản game hoặc đăng nhập

Sheet Test Report
A2: UNIT TEST REPORT
A4: Project Name | B4: =Cover!B4 -> GameRent - Hệ thống cho thuê tài khoản game trực tuyến tự động 24/7 | D4: Creator | E4: =Cover!E4 -> Nhóm 15 - Lớp Kiểm thử phần mềm-1-1-26(N05)
A5: Project Code | B5: =Cover!B5 -> GAMERENT | D5: Reviewer/Approver | E5: =Cover!E5 -> ThS. Phạm Thị Loan
A6: Document Code | B6: =B5&"_"&"Test Report_v1.0" -> GAMERENT_Test Report_v1.0 | D6: Issue Date | E6: 2026-03-24
A7: Notes | B7: Báo cáo tổng hợp kết quả thực thi 100 Unit Test Cases cho 10 Module chức năng cốt lõi của hệ thống GameRent (Vitest Suite - 100% Passed).
A10: No | B10: Function code | C10: Passed | D10: Failed | E10: Untested | F10: N | G10: A | H10: B | I10: Total Test Cases | L10: Status | M10: Count
A11: 1 | B11: F_AUTH_REG | C11: =F_AUTH_REG!A7 -> 16 | D11: =F_AUTH_REG!C7 -> 0 | E11: =F_AUTH_REG!E7 -> 0 | F11: =F_AUTH_REG!K7 -> 3 | G11: =F_AUTH_REG!L7 -> 6 | H11: =F_AUTH_REG!M7 -> 7 | I11: =F_AUTH_REG!N7 -> 16 | L11: Passed | M11: =C16 -> 8
A12: 2 | B12: F_AUTH_LOGIN | C12: =F_AUTH_LOGIN!A7 -> 9 | D12: =F_AUTH_LOGIN!C7 -> 0 | E12: =F_AUTH_LOGIN!E7 -> 0 | F12: =F_AUTH_LOGIN!K7 -> 4 | G12: =F_AUTH_LOGIN!L7 -> 5 | H12: =F_AUTH_LOGIN!M7 -> 0 | I12: =F_AUTH_LOGIN!N7 -> 9 | L12: Failed | M12: =D16 -> 0
A13: 3 | B13: F_WAL_DEP | C13: =F_WAL_DEP!A7 -> 10 | D13: =F_WAL_DEP!C7 -> 0 | E13: =F_WAL_DEP!E7 -> 0 | F13: =F_WAL_DEP!K7 -> 2 | G13: =F_WAL_DEP!L7 -> 2 | H13: =F_WAL_DEP!M7 -> 6 | I13: =F_WAL_DEP!N7 -> 10 | L13: Untested | M13: =E16 -> 0
A14: 4 | B14: F_RENT_CALC | C14: =F_RENT_CALC!A7 -> 14 | D14: =F_RENT_CALC!C7 -> 0 | E14: =F_RENT_CALC!E7 -> 0 | F14: =F_RENT_CALC!K7 -> 6 | G14: =F_RENT_CALC!L7 -> 4 | H14: =F_RENT_CALC!M7 -> 4 | I14: =F_RENT_CALC!N7 -> 14
A15: 5 | B15: F_ADM_PROD | C15: =F_ADM_PROD!A7 -> 15 | D15: =F_ADM_PROD!C7 -> 0 | E15: =F_ADM_PROD!E7 -> 0 | F15: =F_ADM_PROD!K7 -> 1 | G15: =F_ADM_PROD!L7 -> 5 | H15: =F_ADM_PROD!M7 -> 9 | I15: =F_ADM_PROD!N7 -> 15
A16: 6 | B16: F_REF_EXT | C16: =F_REF_EXT!A7 -> 8 | D16: =F_REF_EXT!C7 -> 0 | E16: =F_REF_EXT!E7 -> 0 | F16: =F_REF_EXT!K7 -> 5 | G16: =F_REF_EXT!L7 -> 1 | H16: =F_REF_EXT!M7 -> 2 | I16: =F_REF_EXT!N7 -> 8 | L16: Type | M16: Count
A17: 7 | B17: F_AUTO_PASS | C17: =F_AUTO_PASS!A7 -> 10 | D17: =F_AUTO_PASS!C7 -> 0 | E17: =F_AUTO_PASS!E7 -> 0 | F17: =F_AUTO_PASS!K7 -> 7 | G17: =F_AUTO_PASS!L7 -> 3 | H17: =F_AUTO_PASS!M7 -> 0 | I17: =F_AUTO_PASS!N7 -> 10 | L17: N | M17: =F16 -> 5
A18: 8 | B18: F_AUTH_CHG_PWD | C18: =F_AUTH_CHG_PWD!A7 -> 8 | D18: =F_AUTH_CHG_PWD!C7 -> 0 | E18: =F_AUTH_CHG_PWD!E7 -> 0 | F18: =F_AUTH_CHG_PWD!K7 -> 1 | G18: =F_AUTH_CHG_PWD!L7 -> 5 | H18: =F_AUTH_CHG_PWD!M7 -> 2 | I18: =F_AUTH_CHG_PWD!N7 -> 8 | L18: A | M18: =G16 -> 1
A19: 9 | B19: F_CRM_SYNC | C19: =F_CRM_SYNC!A7 -> 5 | D19: =F_CRM_SYNC!C7 -> 0 | E19: =F_CRM_SYNC!E7 -> 0 | F19: =F_CRM_SYNC!K7 -> 5 | G19: =F_CRM_SYNC!L7 -> 0 | H19: =F_CRM_SYNC!M7 -> 0 | I19: =F_CRM_SYNC!N7 -> 5
A20: 10 | B20: F_FAV_SEP | C20: =F_FAV_SEP!A7 -> 5 | D20: =F_FAV_SEP!C7 -> 0 | E20: =F_FAV_SEP!E7 -> 0 | F20: =F_FAV_SEP!K7 -> 5 | G20: =F_FAV_SEP!L7 -> 0 | H20: =F_FAV_SEP!M7 -> 0 | I20: =F_FAV_SEP!N7 -> 5
B21: Sub total | C21: =SUM(C11:C20) -> 100 | D21: =SUM(D11:D20) -> 0 | E21: =SUM(E11:E20) -> 0 | F21: =SUM(F11:F20) -> 39 | G21: =SUM(G11:G20) -> 31 | H21: =SUM(H11:H20) -> 30 | I21: =SUM(I11:I20) -> 100
B23: Test coverage | D23: =(C21+D21)*100/(I21) -> 100 | E23: %
B24: Test successful coverage | D24: =C21*100/(I21) -> 100 | E24: %
B25: Normal case | D25: =F21*100/I21 -> 39 | E25: %
B26: Abnormal case | D26: =G21*100/I21 -> 31 | E26: %
B27: Boundary case | D27: =H21*100/I21 -> 30 | E27: %

Sheet F_AUTH_REG
A2: Function Code | C2: F_AUTH_REG | E2: Function Name | G2: validateRegistration
A3: Created By | C3: Nhóm 15 | E3: Executed By | G3: Nhóm 15 (Automation)
A4: Lines of code | C4: 52
A5: Test requirement | C5: Kiểm tra hợp lệ form đăng ký tài khoản (BVA 4-30 ký tự, SĐT 10 chữ số, mật khẩu >= 6 ký tự, kiểm tra trùng lặp)
A6: Passed | C6: Failed | E6: Untested | K6: N/A/B | N6: Total Test Cases
A7: =COUNTIF(E49:T49,"P") -> 16 | C7: =COUNTIF(E49:T49,"F") -> 0 | E7: =SUM(N7,-A7,-C7) -> 0 | K7: =COUNTIF(E48:T48,"N") -> 3 | L7: =COUNTIF(E48:T48,"A") -> 6 | M7: =COUNTIF(E48:T48,"B") -> 7 | N7: =COUNTA(E9:T9) -> 16
E9: UTCID01 | F9: UTCID02 | G9: UTCID03 | H9: UTCID04 | I9: UTCID05 | J9: UTCID06 | K9: UTCID07 | L9: UTCID08 | M9: UTCID09 | N9: UTCID10 | O9: UTCID11 | P9: UTCID12 | Q9: UTCID13 | R9: UTCID14 | S9: UTCID15 | T9: UTCID16
A10: Condition | B10: Precondition | D10: N/A
B12: Username
D13: Hợp lệ ('user_valid') | E13: O | N13: O | T13: O
D14: Dưới biên min (3 ký tự: 'abc') | F14: O
D15: Để trống ('') | G15: O
D16: Tại biên max (30 ký tự) | H16: O
D17: Vượt biên max (31 ký tự) | I17: O
D18: Chứa khoảng trắng ('user name') | J18: O
D19: Chứa ký tự đặc biệt ('user@123') | K19: O
D20: Đã tồn tại trong CSDL ('khach01') | S20: O
D21: Có dấu gạch dưới ('vip_pro_01') | T21: O
B22: Password
D23: Hợp lệ (>= 6 ký tự: 'pass123') | E23: O | F23: O | G23: O | H23: O | I23: O | J23: O | K23: O | N23: O | O23: O | P23: O | Q23: O | R23: O | S23: O | T23: O
D24: Tại biên min (6 ký tự: '123456') | L24: O
D25: Dưới biên min (5 ký tự: '12345') | M25: O
B26: Phone
D27: 10 số di động chuẩn ('0987654321') | E27: O | F27: O | G27: O | H27: O | I27: O | J27: O | K27: O | L27: O | M27: O | N27: O
D28: Sai đầu số mạng ('0123456789') | O28: O
D29: Thiếu số (9 số: '098765432') | P29: O
D30: Thừa số (11 số: '09876543210') | Q30: O
D31: Chứa ký tự chữ ('0987abc321') | R31: O
D32: Đầu số 08 chuẩn ('0812345678') | T32: O
A34: Confirm | B34: Return / Exception
D35: isValid = true | E35: O | H35: O | L35: O | N35: O | T35: O
D36: error = 'Tên đăng nhập phải từ 4 ký tự trở lên' | F36: O
D37: error = 'Tên đăng nhập không được để trống' | G37: O
D38: error = 'Tên đăng nhập không được vượt quá 30 ký tự' | I38: O
D39: error = 'Tên đăng nhập không chứa khoảng trắng' | J39: O
D40: error = 'Tên đăng nhập chỉ gồm chữ và số' | K40: O
D41: error = 'Mật khẩu phải có ít nhất 6 ký tự' | M41: O
D42: error = 'Số điện thoại không đúng định dạng đầu số di động' | O42: O
D43: error = 'Số điện thoại phải gồm đúng 10 chữ số' | P43: O
D44: error = 'Số điện thoại không được vượt quá 10 chữ số' | Q44: O
...

Sheet F_AUTH_LOGIN
A2: Function Code | C2: F_AUTH_LOGIN | E2: Function Name | G2: validateLogin
A3: Created By | C3: Nhóm 15 | E3: Executed By | G3: Nhóm 15 (Automation)
A4: Lines of code | C4: 28
A5: Test requirement | C5: Xác thực thông tin đăng nhập email/mật khẩu, chặn tài khoản bị khóa isBlocked, quản lý phiên
A6: Passed | C6: Failed | E6: Untested | K6: N/A/B | N6: Total Test Cases
A7: =COUNTIF(E38:M38,"P") -> 9 | C7: =COUNTIF(E38:M38,"F") -> 0 | E7: =SUM(N7,-A7,-C7) -> 0 | K7: =COUNTIF(E37:M37,"N") -> 4 | L7: =COUNTIF(E37:M37,"A") -> 5 | M7: =COUNTIF(E37:M37,"B") -> 0 | N7: =COUNTA(E9:M9) -> 9
E9: UTCID01 | F9: UTCID02 | G9: UTCID03 | H9: UTCID04 | I9: UTCID05 | J9: UTCID06 | K9: UTCID07 | L9: UTCID08 | M9: UTCID09
A10: Condition | B10: Precondition | D10: N/A
B12: Email
D13: Email chính xác ('khach01@gmail.com') | E13: O | F13: O | I13: O | J13: O
D14: Email không tồn tại ('notfound@gmail.com') | G14: O
D15: Email để trống ('') | H15: O
D16: Tài khoản đang đăng nhập hợp lệ | K16: O | M16: O
D17: Chưa có phiên (LocalStorage trống) | L17: O
B18: Password
D19: Đúng mật khẩu ('123456') | E19: O | G19: O | H19: O | J19: O
D20: Sai mật khẩu ('wrongpass') | F20: O
D21: Để trống mật khẩu ('') | I21: O
B22: Trạng thái
D23: Hoạt động bình thường (isBlocked=false) | E23: O | F23: O | G23: O | H23: O | I23: O | K23: O | L23: O | M23: O
D24: Bị khóa vi phạm (isBlocked=true) | J24: O
A26: Confirm | B26: Return / Exception
D27: success = true, user != null | E27: O
D28: error = 'Mật khẩu không chính xác' | F28: O
D29: error = 'Email không tồn tại trên hệ thống' | G29: O
D30: error = 'Email không được để trống' | H30: O
D31: error = 'Mật khẩu không được để trống' | I31: O
D32: error = 'Tài khoản của bạn đang bị khóa do vi phạm quy chế' | J32: O
D33: Khôi phục phiên đăng nhập thành công | K33: O
D34: Khởi động ở trạng thái Guest (chưa đăng nhập) | L34: O
D35: Xóa sạch phiên, chuyển về trạng thái Guest | M35: O
A37: Result | B37: Type(N : Normal, A : Abnormal, B : Boundary) | E37: N | F37: A | G37: A | H37: A | I37: A | J37: A | K37: N | L37: N | M37: N
B38: Passed/Failed | E38: P | F38: P | G38: P | H38: P | I38: P | J38: P | K38: P | L38: P | M38: P
B39: Executed Date | E39: 2026-03-24 | F39: 2026-03-24 | G39: 2026-03-24 | H39: 2026-03-24 | I39: 2026-03-24 | J39: 2026-03-24 | K39: 2026-03-24 | L39: 2026-03-24 | M39: 2026-03-24
B40: Defect ID

Sheet F_WAL_DEP
A2: Function Code | C2: F_WAL_DEP | E2: Function Name | G2: validateDepositAmount
A3: Created By | C3: Nhóm 15 | E3: Executed By | G3: Nhóm 15 (Automation)
A4: Lines of code | C4: 20
A5: Test requirement | C5: Kiểm tra hợp lệ hạn mức nạp tiền ví qua VietQR Auto (BVA 10.000đ - 5.000.000đ, số nguyên dương)
A6: Passed | C6: Failed | E6: Untested | K6: N/A/B | N6: Total Test Cases
A7: =COUNTIF(E32:N32,"P") -> 10 | C7: =COUNTIF(E32:N32,"F") -> 0 | E7: =SUM(N7,-A7,-C7) -> 0 | K7: =COUNTIF(E31:N31,"N") -> 2 | L7: =COUNTIF(E31:N31,"A") -> 2 | M7: =COUNTIF(E31:N31,"B") -> 6 | N7: =COUNTA(E9:N9) -> 10
E9: UTCID01 | F9: UTCID02 | G9: UTCID03 | H9: UTCID04 | I9: UTCID05 | J9: UTCID06 | K9: UTCID07 | L9: UTCID08 | M9: UTCID09 | N9: UTCID10
A10: Condition | B10: Precondition | D10: N/A
B12: Số tiền nạp (VNĐ)
D13: 9.999 VNĐ (Ngay dưới biên min) | E13: O
D14: 10.000 VNĐ (Tại biên min hợp lệ) | F14: O
D15: 11.000 VNĐ (Ngay trên biên min) | G15: O
D16: 200.000 VNĐ (Gói nạp thông dụng) | H16: O
D17: 1.000.000 VNĐ (Gói nạp VIP) | I17: O
D18: 4.999.000 VNĐ (Ngay dưới biên max) | J18: O
D19: 5.000.000 VNĐ (Tại biên max hợp lệ) | K19: O
D20: 5.001.000 VNĐ (Vượt quá biên max) | L20: O
D21: -50.000 VNĐ (Số tiền âm) | M21: O
D22: 'abc@123' (Ký tự chữ / ký tự đặc biệt) | N22: O
A24: Confirm | B24: Return / Exception
D25: isValid = true, amount xác định | F25: O | G25: O | H25: O | I25: O | J25: O | K25: O
D26: error = 'Số tiền nạp tối thiểu là 10.000 VNĐ' | E26: O
D27: error = 'Số tiền nạp tối đa là 5.000.000 VNĐ' | L27: O
D28: error = 'Số tiền nạp phải là số nguyên dương' | M28: O
D29: error = 'Vui lòng nhập số tiền hợp lệ' | N29: O
A31: Result | B31: Type(N : Normal, A : Abnormal, B : Boundary) | E31: B | F31: B | G31: B | H31: N | I31: N | J31: B | K31: B | L31: B | M31: A | N31: A
B32: Passed/Failed | E32: P | F32: P | G32: P | H32: P | I32: P | J32: P | K32: P | L32: P | M32: P | N32: P
B33: Executed Date | E33: 2026-03-24 | F33: 2026-03-24 | G33: 2026-03-24 | H33: 2026-03-24 | I33: 2026-03-24 | J33: 2026-03-24 | K33: 2026-03-24 | L33: 2026-03-24 | M33: 2026-03-24 | N33: 2026-03-24
B34: Defect ID

Sheet F_RENT_CALC
A2: Function Code | C2: F_RENT_CALC | E2: Function Name | G2: calculateRentalCost
A3: Created By | C3: Nhóm 15 | E3: Executed By | G3: Nhóm 15 (Automation)
A4: Lines of code | C4: 42
A5: Test requirement | C5: Tính chi phí thuê và kiểm tra số dư ví theo Decision Table (BVA 1h - 48h, trạng thái acc, đủ/thiếu ví)
A6: Passed | C6: Failed | E6: Untested | K6: N/A/B | N6: Total Test Cases
A7: =COUNTIF(E42:R42,"P") -> 14 | C7: =COUNTIF(E42:R42,"F") -> 0 | E7: =SUM(N7,-A7,-C7) -> 0 | K7: =COUNTIF(E41:R41,"N") -> 6 | L7: =COUNTIF(E41:R41,"A") -> 4 | M7: =COUNTIF(E41:R41,"B") -> 4 | N7: =COUNTA(E9:R9) -> 14
E9: UTCID01 | F9: UTCID02 | G9: UTCID03 | H9: UTCID04 | I9: UTCID05 | J9: UTCID06 | K9: UTCID07 | L9: UTCID08 | M9: UTCID09 | N9: UTCID10 | O9: UTCID11 | P9: UTCID12 | Q9: UTCID13 | R9: UTCID14
A10: Condition | B10: Precondition | D10: N/A
B12: Số giờ thuê
D13: 1 giờ (Tại biên min) | E13: O | I13: O | J13: O | K13: O | L13: O | M13: O | N13: O
D14: 0 giờ (Dưới biên min) | F14: O
D15: 48 giờ (Tại biên max) | G15: O
D16: 49 giờ (Vượt biên max) | H16: O
D17: Thời gian hợp lệ khác | O17: O | P17: O | Q17: O | R17: O
B18: Số dư ví khách
D19: Đủ tiền (> chi phí: 50k > 30k) | E19: O | G19: O | I19: O | O19: O | P19: O | Q19: O | R19: O
D20: Vừa đủ tiền (== chi phí: 30k == 30k) | J20: O
D21: Thiếu tiền (< chi phí: 20k < 30k) | K21: O
D22: Hết tiền (0 VNĐ) | L22: O
B23: Trạng thái tài khoản
D24: available (Sẵn sàng) | E24: O | F24: O | G24: O | H24: O | I24: O | J24: O | K24: O | L24: O | O24: O | P24: O | Q24: O | R24: O
D25: rented (Đang có người thuê) | M25: O
D26: maintenance (Đang bảo trì) | N26: O
A28: Confirm | B28: Return / Exception
D29: canRent = true, tính đúng totalCost | E29: O | G29: O | I29: O | J29: O
D30: error = 'Thời gian thuê tối thiểu là 1 giờ' | F30: O
D31: error = 'Thời gian thuê tối đa là 48 giờ' | H31: O
D32: canRent = false, báo thiếu 10.000 đ | K32: O
D33: canRent = false, báo thiếu 30.000 đ | L33: O
D34: error = 'Tài khoản này hiện đang có người thuê' | M34: O
D35: error = 'Tài khoản đang trong quá trình bảo trì / đổi mật khẩu' | N35: O
D36: Lọc chính xác theo tựa game (LQ, Val, Genshin) | O36: O
D37: Tìm kiếm chính xác theo mã đơn, mã acc | P37: O
D38: Tìm kiếm linh hoạt theo tên khách (có/không dấu) | Q38: O
D39: Tìm kiếm chính xác theo tên tựa game | R39: O
A41: Result | B41: Type(N : Normal, A : Abnormal, B : Boundary) | E41: B | F41: B | G41: B | H41: B | I41: N | J41: N | K41: A | L41: A | M41: A | N41: A | O41: N | P41: N | Q41: N | R41: N
B42: Passed/Failed | E42: P | F42: P | G42: P | H42: P | I42: P | J42: P | K42: P | L42: P | M42: P | N42: P | O42: P | P42: P | Q42: P | R42: P
B43: Executed Date | E43: 2026-03-24 | F43: 2026-03-24 | G43: 2026-03-24 | H43: 2026-03-24 | I43: 2026-03-24 | J43: 2026-03-24 | K43: 2026-03-24 | L43: 2026-03-24 | M43: 2026-03-24 | N43: 2026-03-24 | O43: 2026-03-24 | P43: 2026-03-24 | Q43: 2026-03-24 | R43: 2026-03-24
B44: Defect ID

Sheet F_ADM_PROD
A2: Function Code | C2: F_ADM_PROD | E2: Function Name | G2: validateProductUC1
A3: Created By | C3: Nhóm 15 | E3: Executed By | G3: Nhóm 15 (Automation)
A4: Lines of code | C4: 58
A5: Test requirement | C5: Kiểm tra form Thêm tài khoản game chuẩn 100% tài liệu đặc tả đề bài UC1_Add New Product (BR1-BR6)
A6: Passed | C6: Failed | E6: Untested | K6: N/A/B | N6: Total Test Cases
A7: =COUNTIF(E48:S48,"P") -> 15 | C7: =COUNTIF(E48:S48,"F") -> 0 | E7: =SUM(N7,-A7,-C7) -> 0 | K7: =COUNTIF(E47:S47,"N") -> 1 | L7: =COUNTIF(E47:S47,"A") -> 5 | M7: =COUNTIF(E47:S47,"B") -> 9 | N7: =COUNTA(E9:S9) -> 15
E9: UTCID01 | F9: UTCID02 | G9: UTCID03 | H9: UTCID04 | I9: UTCID05 | J9: UTCID06 | K9: UTCID07 | L9: UTCID08 | M9: UTCID09 | N9: UTCID10 | O9: UTCID11 | P9: UTCID12 | Q9: UTCID13 | R9: UTCID14 | S9: UTCID15
A10: Condition | B10: Precondition | D10: N/A
B12: Mã sản phẩm
D13: 7 ký tự (Dưới biên min 8) | E13: O
D14: 8 ký tự (Biên min hợp lệ) | F14: O
D15: 30 ký tự (Biên max hợp lệ) | G15: O
D16: 31 ký tự (Vượt biên max 30) | H16: O
D17: Chứa ký tự đặc biệt ('@') | I17: O
D18: Chứa khoảng trắng | J18: O
D19: Đã tồn tại trong CSDL ('ACCVAL001') | K19: O
D20: Hợp lệ ('ACCVAL01') | L20: O | M20: O | N20: O | O20: O | P20: O | Q20: O | R20: O | S20: O
B21: Tên sản phẩm
D22: 9 ký tự (Dưới biên min 10) | L22: O
D23: 10 ký tự (Biên min hợp lệ) | M23: O
D24: 50 ký tự (Biên max hợp lệ) | N24: O
D25: 51 ký tự (Vượt biên max 50) | O25: O
D26: Hợp lệ (10-50 ký tự) | E26: O | F26: O | G26: O | H26: O | I26: O | J26: O | K26: O | P26: O | Q26: O | R26: O | S26: O
B27: Hình ảnh & Giá
D28: Sai định dạng ảnh (.pdf, .zip) | P28: O
D29: Dung lượng ảnh 1.5MB (> 1MB) | Q29: O
D30: Ảnh PNG 800KB hợp lệ (<= 1MB) | E30: O | F30: O | G30: O | H30: O | I30: O | J30: O | K30: O | L30: O | M30: O | N30: O | O30: O | R30: O
D31: Giá thuê âm (-10.000 VNĐ) | S31: O
D32: Giá thuê hợp lệ (> 0) | E32: O | F32: O | G32: O | H32: O | I32: O | J32: O | K32: O | L32: O | M32: O | N32: O | O32: O | P32: O | Q32: O | R32: O
A34: Confirm | B34: Return / Exception
D35: isValid = true (Thêm sản phẩm thành công) | F35: O | G35: O | M35: O | N35: O | R35: O
D36: error = 'Mã sản phẩm phải từ 8 ký tự trở lên' | E36: O
D37: error = 'Mã sản phẩm không vượt quá 30 ký tự' | H37: O
D38: error = 'Mã sản phẩm chỉ gồm chữ và số' | I38: O
D39: error = 'Mã sản phẩm không chứa khoảng trắng' | J39: O
D40: error = 'Mã sản phẩm đã tồn tại trong hệ thống' | K40: O
D41: error = 'Tên sản phẩm phải từ 10 ký tự trở lên' | L41: O
D42: error = 'Tên sản phẩm không quá 50 ký tự' | O42: O
D43: error = 'Ảnh phải đúng định dạng (.jpg, .png, .gif)' | P43: O
D44: error = 'Dung lượng ảnh vượt quá 1MB' | Q44: O
...

Sheet F_REF_EXT
A2: Function Code | C2: F_REF_EXT | E2: Function Name | G2: calculateRefundAndExtension
A3: Created By | C3: Nhóm 15 | E3: Executed By | G3: Nhóm 15 (Automation)
A4: Lines of code | C4: 48
A5: Test requirement | C5: Tính hoàn tiền 50% khi trả sớm, hoàn tiền 100% khi khiếu nại được duyệt, và gia hạn thêm giờ thuê
A6: Passed | C6: Failed | E6: Untested | K6: N/A/B | N6: Total Test Cases
A7: =COUNTIF(E37:L37,"P") -> 8 | C7: =COUNTIF(E37:L37,"F") -> 0 | E7: =SUM(N7,-A7,-C7) -> 0 | K7: =COUNTIF(E36:L36,"N") -> 5 | L7: =COUNTIF(E36:L36,"A") -> 1 | M7: =COUNTIF(E36:L36,"B") -> 2 | N7: =COUNTA(E9:L9) -> 8
E9: UTCID01 | F9: UTCID02 | G9: UTCID03 | H9: UTCID04 | I9: UTCID05 | J9: UTCID06 | K9: UTCID07 | L9: UTCID08
A10: Condition | B10: Precondition | D10: N/A
B12: Hành động
D13: Trả tài khoản sớm (return_early) | E13: O | F13: O
D14: Duyệt bồi thường khiếu nại (dispute_approved) | G14: O | H14: O
D15: Gia hạn thêm giờ (extend) | I15: O | J15: O | K15: O | L15: O
B16: Thời gian / Điều kiện
D17: Còn 2 giờ thừa (30.000 đ/h) | E17: O
D18: Đã hết giờ chơi (0 giờ thừa) | F18: O
D19: Đơn hàng giá trị 30.000 đ | G19: O
D20: Đơn hàng giá trị 50.000 đ | H20: O
D21: Gia hạn thêm 1 giờ khi còn hạn | I21: O
D22: Gia hạn thêm 24 giờ | J22: O
D23: Gia hạn khi đơn đã quá hạn | K23: O
D24: Số giờ gia hạn <= 0 | L24: O
A26: Confirm | B26: Return / Exception
D27: Hoàn 50% = 30.000 đ, orderStatus = 'completed' | E27: O
D28: Hoàn 0 đ | F28: O
D29: Hoàn 100% = 30.000 đ, accountStatus = 'maintenance' | G29: O
D30: Hoàn 100% = 50.000 đ | H30: O
D31: Cộng nối tiếp 3.600s vào expiresAt, phí 15k | I31: O
D32: Cộng nối tiếp 24h, chi phí 360.000 đ | J32: O
D33: Tính mốc mới bắt đầu từ Date.now() | K33: O
D34: error = 'Số giờ gia hạn phải lớn hơn 0' | L34: O
A36: Result | B36: Type(N : Normal, A : Abnormal, B : Boundary) | E36: N | F36: B | G36: N | H36: N | I36: N | J36: N | K36: B | L36: A
B37: Passed/Failed | E37: P | F37: P | G37: P | H37: P | I37: P | J37: P | K37: P | L37: P
B38: Executed Date | E38: 2026-03-24 | F38: 2026-03-24 | G38: 2026-03-24 | H38: 2026-03-24 | I38: 2026-03-24 | J38: 2026-03-24 | K38: 2026-03-24 | L38: 2026-03-24
B39: Defect ID

Sheet F_AUTO_PASS
A2: Function Code | C2: F_AUTO_PASS | E2: Function Name | G2: generateRandomPassword
A3: Created By | C3: Nhóm 15 | E3: Executed By | G3: Nhóm 15 (Automation)
A4: Lines of code | C4: 32
A5: Test requirement | C5: Tự động sinh mật khẩu ngẫu nhiên bảo mật cao (12-14 ký tự) khi thu hồi nick hết giờ, chống trùng pass cũ
A6: Passed | C6: Failed | E6: Untested | K6: N/A/B | N6: Total Test Cases
A7: =COUNTIF(E38:N38,"P") -> 10 | C7: =COUNTIF(E38:N38,"F") -> 0 | E7: =SUM(N7,-A7,-C7) -> 0 | K7: =COUNTIF(E37:N37,"N") -> 7 | L7: =COUNTIF(E37:N37,"A") -> 3 | M7: =COUNTIF(E37:N37,"B") -> 0 | N7: =COUNTA(E9:N9) -> 10
E9: UTCID01 | F9: UTCID02 | G9: UTCID03 | H9: UTCID04 | I9: UTCID05 | J9: UTCID06 | K9: UTCID07 | L9: UTCID08 | M9: UTCID09 | N9: UTCID10
A10: Condition | B10: Precondition | D10: N/A
B12: Mật khẩu cũ
D13: Có mật khẩu cũ cụ thể ('OldPass@123') | E13: O | F13: O | G13: O | H13: O | K13: O | L13: O
D14: Không truyền mật khẩu cũ ('') | I14: O | J14: O | M14: O | N14: O
B15: Kịch bản kích hoạt
D16: Sinh mật khẩu đơn lẻ | E16: O | F16: O | G16: O
D17: 50 lần sinh liên tiếp | H17: O
D18: Thu hồi nick chuyển trạng thái available | I18: O
D19: Kiểm tra toàn bộ kho acc | J19: O
D20: Lưu vết lịch sử mật khẩu | K20: O
D21: Vô hiệu hóa mật khẩu cũ | L21: O
D22: Tạo thông báo hết hạn ca thuê | M22: O
D23: Vòng đời đọc/xóa thông báo chuông | N23: O
A25: Confirm | B25: Return / Exception
D26: Độ dài mật khẩu chuẩn 12-14 ký tự | E26: O
D27: Chứa đầy đủ [A-Z], [a-z], [0-9], [@#!] | F27: O
D28: newPassword !== oldPassword (không trùng) | G28: O
D29: 50 chuỗi mật khẩu hoàn toàn khác biệt | H29: O
D30: Trạng thái acc chuyển sang 'available' | I30: O
D31: secretAccount & secretPassword hợp lệ | J31: O
D32: Lưu vết lịch sử mật khẩu thành công | K32: O
D33: Mật khẩu cũ bị vô hiệu hóa hoàn toàn | L33: O
D34: Tự động tạo notification cho khách | M34: O
D35: Đánh dấu đã đọc và xóa thông báo thành công | N35: O
A37: Result | B37: Type(N : Normal, A : Abnormal, B : Boundary) | E37: N | F37: N | G37: N | H37: N | I37: N | J37: N | K37: N | L37: A | M37: A | N37: A
B38: Passed/Failed | E38: P | F38: P | G38: P | H38: P | I38: P | J38: P | K38: P | L38: P | M38: P | N38: P
B39: Executed Date | E39: 2026-03-24 | F39: 2026-03-24 | G39: 2026-03-24 | H39: 2026-03-24 | I39: 2026-03-24 | J39: 2026-03-24 | K39: 2026-03-24 | L39: 2026-03-24 | M39: 2026-03-24 | N39: 2026-03-24
B40: Defect ID

Sheet F_AUTH_CHG_PWD
A2: Function Code | C2: F_AUTH_CHG_PWD | E2: Function Name | G2: validatePasswordChange
A3: Created By | C3: Nhóm 15 | E3: Executed By | G3: Nhóm 15 (Automation)
A4: Lines of code | C4: 26
A5: Test requirement | C5: Kiểm tra hợp lệ form đổi mật khẩu khách thuê (BVA 5-6 ký tự, mật khẩu cũ, khớp mật khẩu xác nhận)
A6: Passed | C6: Failed | E6: Untested | K6: N/A/B | N6: Total Test Cases
A7: =COUNTIF(E36:L36,"P") -> 8 | C7: =COUNTIF(E36:L36,"F") -> 0 | E7: =SUM(N7,-A7,-C7) -> 0 | K7: =COUNTIF(E35:L35,"N") -> 1 | L7: =COUNTIF(E35:L35,"A") -> 5 | M7: =COUNTIF(E35:L35,"B") -> 2 | N7: =COUNTA(E9:L9) -> 8
E9: UTCID01 | F9: UTCID02 | G9: UTCID03 | H9: UTCID04 | I9: UTCID05 | J9: UTCID06 | K9: UTCID07 | L9: UTCID08
A10: Condition | B10: Precondition | D10: N/A
B12: User đăng nhập
D13: Hợp lệ (user != null) | E13: O | F13: O | G13: O | H13: O | I13: O | J13: O | K13: O
D14: Chưa đăng nhập (user = null) | L14: O
B15: Mật khẩu hiện tại
D16: Đúng mật khẩu ('123456') | E16: O | F16: O | G16: O | I16: O | J16: O
D17: Sai mật khẩu ('wrongpass') | H17: O
D18: Để trống ('') | K18: O
B19: Mật khẩu mới
D20: Hợp lệ ('newpass123') | E20: O | H20: O | K20: O | L20: O
D21: 5 ký tự (Dưới biên min 6) | F21: O
D22: 6 ký tự (Tại biên min hợp lệ) | G22: O
D23: Trùng mật khẩu cũ ('123456') | I23: O
D24: Không khớp mật khẩu xác nhận | J24: O
A26: Confirm | B26: Return / Exception
D27: success = true (Đổi mật khẩu thành công) | E27: O | G27: O
D28: error = 'Mật khẩu mới phải có ít nhất 6 ký tự' | F28: O
D29: error = 'Mật khẩu hiện tại không chính xác' | H29: O
D30: error = 'Mật khẩu mới không được trùng mật khẩu cũ' | I30: O
D31: error = 'Mật khẩu xác nhận không khớp' | J31: O
D32: error = 'Vui lòng nhập mật khẩu hiện tại' | K32: O
D33: error = 'Bạn chưa đăng nhập' | L33: O
A35: Result | B35: Type(N : Normal, A : Abnormal, B : Boundary) | E35: N | F35: B | G35: B | H35: A | I35: A | J35: A | K35: A | L35: A
B36: Passed/Failed | E36: P | F36: P | G36: P | H36: P | I36: P | J36: P | K36: P | L36: P
B37: Executed Date | E37: 2026-03-24 | F37: 2026-03-24 | G37: 2026-03-24 | H37: 2026-03-24 | I37: 2026-03-24 | J37: 2026-03-24 | K37: 2026-03-24 | L37: 2026-03-24
B38: Defect ID

Sheet F_CRM_SYNC
A2: Function Code | C2: F_CRM_SYNC | E2: Function Name | G2: crudAndAutoSyncCRM
A3: Created By | C3: Nhóm 15 | E3: Executed By | G3: Nhóm 15 (Automation)
A4: Lines of code | C4: 35
A5: Test requirement | C5: Thao tác CRUD hồ sơ khách hàng và tự động đồng bộ khách mới khi đăng ký
A6: Passed | C6: Failed | E6: Untested | K6: N/A/B | N6: Total Test Cases
A7: =COUNTIF(E27:I27,"P") -> 5 | C7: =COUNTIF(E27:I27,"F") -> 0 | E7: =SUM(N7,-A7,-C7) -> 0 | K7: =COUNTIF(E26:I26,"N") -> 5 | L7: =COUNTIF(E26:I26,"A") -> 0 | M7: =COUNTIF(E26:I26,"B") -> 0 | N7: =COUNTA(E9:I9) -> 5
E9: UTCID01 | F9: UTCID02 | G9: UTCID03 | H9: UTCID04 | I9: UTCID05
A10: Condition | B10: Precondition | D10: N/A
B12: Thao tác CRM
D13: Thêm khách hàng thủ công | E13: O
D14: Cập nhật thông tin khách (SĐT, Email, Status) | F14: O
D15: Xóa khách hàng khỏi hệ thống | G15: O
D16: Cập nhật thông tin tài khoản kho game | H16: O
D17: Khách đăng ký mới ngoài trang chủ | I17: O
A19: Confirm | B19: Return / Exception
D20: Thêm thành công khách hàng mới (KH00x) | E20: O
D21: Thông tin khách hàng được cập nhật chính xác | F21: O
D22: Khách hàng bị xóa thành công khỏi CRM | G22: O
D23: Kho tài khoản game được cập nhật thành công | H23: O
D24: Tự động đồng bộ ngay lập tức sang CRM Admin | I24: O
A26: Result | B26: Type(N : Normal, A : Abnormal, B : Boundary) | E26: N | F26: N | G26: N | H26: N | I26: N
B27: Passed/Failed | E27: P | F27: P | G27: P | H27: P | I27: P
B28: Executed Date | E28: 2026-03-24 | F28: 2026-03-24 | G28: 2026-03-24 | H28: 2026-03-24 | I28: 2026-03-24
B29: Defect ID

Sheet F_FAV_SEP
A2: Function Code | C2: F_FAV_SEP | E2: Function Name | G2: getFavoritesKey
A3: Created By | C3: Nhóm 15 | E3: Executed By | G3: Nhóm 15 (Automation)
A4: Lines of code | C4: 22
A5: Test requirement | C5: Xác định chính xác storage key phân tách danh sách yêu thích độc lập theo User ID
A6: Passed | C6: Failed | E6: Untested | K6: N/A/B | N6: Total Test Cases
A7: =COUNTIF(E26:I26,"P") -> 5 | C7: =COUNTIF(E26:I26,"F") -> 0 | E7: =SUM(N7,-A7,-C7) -> 0 | K7: =COUNTIF(E25:I25,"N") -> 5 | L7: =COUNTIF(E25:I25,"A") -> 0 | M7: =COUNTIF(E25:I25,"B") -> 0 | N7: =COUNTA(E9:I9) -> 5
E9: UTCID01 | F9: UTCID02 | G9: UTCID03 | H9: UTCID04 | I9: UTCID05
A10: Condition | B10: Precondition | D10: N/A
B12: Vai trò & Người dùng
D13: Tài khoản Quản trị viên (Admin) | E13: O | H13: O
D14: Khách hàng User 1 | F14: O | H14: O | I14: O
D15: Khách hàng User 2 | I15: O
D16: Khách vãng lai (Chưa đăng nhập) | G16: O
A18: Confirm | B18: Return / Exception
D19: Key chuẩn: 'gamerent_fav_admin_01' | E19: O
D20: Key chuẩn: 'gamerent_fav_user_02' | F20: O
D21: Key chuẩn: 'gamerent_fav_guest' | G21: O
D22: Dữ liệu tim của Admin không lẫn sang User | H22: O
D23: Hai khách hàng có danh sách tim độc lập 100% | I23: O
A25: Result | B25: Type(N : Normal, A : Abnormal, B : Boundary) | E25: N | F25: N | G25: N | H25: N | I25: N
B26: Passed/Failed | E26: P | F26: P | G26: P | H26: P | I26: P
B27: Executed Date | E27: 2026-03-24 | F27: 2026-03-24 | G27: 2026-03-24 | H27: 2026-03-24 | I27: 2026-03-24
B28: Defect ID
